<?xml version="1.0"?>
<robot xmlns:xacro="http://www.ros.org/wiki/xacro" >

    <xacro:include filename="inertial_macros.xacro" />

    <material name="white">
        <color rgba="1 1 1 1"/>
    </material>

    <material name="blue">
        <color rgba="1 0.3 0.1 1"/>
    </material>

    <material name="blurrywood">
        <color rgba="1 0.4 0.2 1"/>
    </material>

    <material name="black">
        <color rgba="0 0 0 1"/>
    </material>

    <material name="orange">
        <color rgba="1 0.3 0.1 1"/>
    </material>

    <!--BASE LINK-->

    <link name="base_link">

    </link>

    <!-- BASE FOOTPRINT -->

    <!-- <joint name="base_footprint_joint" type="fixed">
        <parent link="base_link"/>
        <child link="base_footprint"/>
        <origin xyz="0 0 0" rpy="0 0 0"/>
    </joint>

    <link name="base_footprint">
    </link> -->

    <!--CHASSIS LINK-->

    <joint name="chassis_joint" type="fixed">
        <parent link="base_link"/>
        <child link="chassis"/>
        <origin xyz="-0.1 0 0"/>
    </joint>

    <link name="chassis">
        <visual>
            <origin xyz="0.25 0 0.1" />
            <geometry>
                <box size="0.5 0.3 0.2" />
            </geometry>oo
            <material name="blurrywood" />
        </visual>
        <collision>
            <origin xyz="0.25 0 0.1" />
            <geometry>
                <box size="0.5 0.3 0.2" />
            </geometry>
        </collision>
        <xacro:inertial_box mass="0.5" x="0.5" y="0.3" z="0.2">
            <origin xyz="0.25 0 0.1" rpy="0 0 0"/>
        </xacro:inertial_box>
    </link>

    <gazebo reference="chassis">
        <material>
            Gazebo/Orange
        </material>
    </gazebo>

    <!-- LEFT WHEEL LINK-->

    <joint name="left_wheel_joint" type="continuous">
        <parent link="base_link" />
        <child link="left_wheel" />
        <origin xyz="0 0.175 0" rpy="-${pi/2} 0 0" />
        <axis xyz="0 0 1"/>
    </joint>

    <link name="left_wheel">
        <visual>
            <geometry>
                <cylinder radius="0.05" length="0.04" />
            </geometry>
            <material name="black" />
        </visual>
        <collision>
            <geometry>
                <sphere radius="0.05" />
            </geometry>
        </collision>
        <xacro:inertial_cylinder mass="0.1" length="0.04" radius="0.05">
            <origin xyz="0 0 0" rpy="0 0 0"/>
        </xacro:inertial_cylinder>
    </link>

    <gazebo reference="left_wheel">
        <material>
            Gazebo/Black
        </material>
    </gazebo>

    <!-- RIGHT WHEEL LINK-->

    <joint name="right_wheel_joint" type="continuous">
        <parent link="base_link" />
        <child link="right_wheel" />
        <origin xyz="0 -0.175 0" rpy="${pi/2} 0 0" />
        <axis xyz="0 0 -1"/>
    </joint>

    <link name="right_wheel">
        <visual>
            <geometry>
                <cylinder radius="0.05" length="0.04" />
            </geometry>
            <material name="black" />
        </visual>
        <collision>
            <geometry>
                <sphere radius="0.05" />
            </geometry>
        </collision>
        <xacro:inertial_cylinder mass="0.1" length="0.04" radius="0.05">
            <origin xyz="0 0 0" rpy="0 0 0"/>
        </xacro:inertial_cylinder>
    </link>

    <gazebo reference="right_wheel">
        <material>
            Gazebo/Black
        </material>
    </gazebo>

    <!-- LEFT CASTER WHEELS LINK-->

    <joint name="left_caster_wheel_joint" type="fixed">
        <parent link="chassis" />
        <child link="left_caster_wheel" />
        <origin xyz="0.4 0.175 0" rpy="-${pi/2} 0 0"/>
        <axis xyz="0 0 1"/>
    </joint>

    <link name="left_caster_wheel">
        <visual>
            <geometry>
                <cylinder radius="0.05" length="0.04"/>
            </geometry>
            <material name="black" />
        </visual>
        <collision>
            <geometry>
                <cylinder radius="0.05" length="0.04"/>
            </geometry>
        </collision>
        <xacro:inertial_cylinder mass="0.1" length="0.04" radius="0.05">
            <origin xyz="0 0 0" rpy="0 0 0"/>
        </xacro:inertial_cylinder>
    </link>

    <gazebo reference="left_caster_wheel">
        <material>
            Gazebo/Black
        </material>
        <mu1 value="0.01" />
        <mu2 value="0.01" />
    </gazebo>

        <!-- RIGHT CASTER WHEELS LINK-->

        <joint name="right_caster_wheel_joint" type="fixed">
            <parent link="chassis" />
            <child link="right_caster_wheel" />
            <origin xyz="0.4 -0.175 0" rpy="${pi/2} 0 0"/>
            <axis xyz="0 0 -1"/>
        </joint>
    
        <link name="right_caster_wheel">
            <visual>
                <geometry>
                    <cylinder radius="0.05" length="0.04"/>
                </geometry>
                <material name="black" />
            </visual>
            <collision>
                <geometry>
                    <cylinder radius="0.05" length="0.04"/>
                </geometry>
            </collision>
            <xacro:inertial_cylinder mass="0.1" length="0.04" radius="0.05">
                <origin xyz="0 0 0" rpy="0 0 0"/>
            </xacro:inertial_cylinder>
        </link>

        <gazebo reference="right_caster_wheel">
            <material>
                Gazebo/Black
            </material>
            <mu1 value="0.01" />
            <mu2 value="0.01" />
        </gazebo>

</robot>